<!--
原始xml来源：https://github.com/Motphys/MotrixLab/blob/main/motrix_envs/src/motrix_envs/basic/manipulator/manipulator_bring_ball.xml

对原始 xml 进行以下微调：
1. 在<worldbody>内部添加用于课程学习的 Wall
2. 修改 timestep="0.01"
3. (可选) 修改“fixed”相机位置和视野

xml 解读:
1. 通过下列两点可以判断本 xml 对应的任务是平面任务
    1. arm 定义中: hinge：所有转动关节都绕着 Y 轴（axis=0 -1 0）转动
    2. ball定义中: slide：沿 x,z 轴滑动；hinge：绕 y 轴旋转；没有沿 y 轴的 slide 关节，说明球在平面内移动
2. xml 的不同组件：
    1. Geom ID: 几何外观，如墙高
    2. SITE ID: 标记点世界坐标,计算目标距离；data.site_xpos[site_id]，调用 site（标记点）的世界坐标
    3. Body ID: 质量、惯性、质心世界坐标；data.xpos[body_id]调用 body 的质心世界坐标
    4. Joint ID: 关节位置、速度等状态信息；通过 self.model.jnt_range[joint_id] 获取关节的动作范围
    - env.py 中自定义 _init_ids，缓存关节 id
3. 搜索整个文档的 site 标记点：
    1. 在 <body name="hand" pos="0 0 .12"> 分支中   # 手掌
      1. <site name="palm_touch" type="box" pos="0 0 .043" size=".025 .005 .008"/>  # 相对于 hand z 轴向前.043，是个 box(有体积的区域)；用来检测物体有没有贴在掌心 # || object_pos - palm_touch || 判断是否贴掌
      2. <site name="grasp" pos="0 0 .065"/>       # 相对于 hand z 轴向前.065，用来代表整只手掌的位置 # || object_pos - grasp || 判断是否“包住”
      3. <body name="pinch site" pos="0 0 .090">   # 相对于 hand z 轴向前.090，两个指尖“闭合后会碰到”的那个点，用于“夹取逻辑“ # distance = || object_pos - pinch || 对齐物体
            <site name="pinch"/>
          </body>
      可见上述 3 个 site 标记点都在一条直线上！“手的抓取轴（approach axis）”
    2. 同样在 <body name="hand" pos="0 0 .12"> 分支中   # 手掌
      1. <body name="thumb" pos=".03 0 .045" euler="0 -90 0" childclass="hand">
          <site name="thumb_touch" group="4"/>
          <body name="thumbtip" pos=".05 0 -.01" childclass="fingertip">
            <site  name="thumbtip_touch" group="4"/>   # 拇指尖；用于真正的夹取逻辑
      2.  同样的定义了 <site name="fingertip_touch"/>    # 食指尖
    3. 对于 ball 来说，body 内部定义的 site 没有设置偏移，故通过 site 和 body 获取的世界坐标都是质心位置
4. mocap="true" 设置 target 虚拟点

和 env.py 的交互：
    - 导入和变量储存：
      - self.model (MjModel)—静态参数 (如 self.wall_height)
      - self.data (MjData)—动态参数 (如 self.data.qpos, self.data.xpos)

核心功能总结：
1. `.xml` 文件基于 MuJoCo 规范构建了系统的底层物理与运动学基座。我将其核心功能分为两面：
	1. [构建物理模型] (配合 MuJoCo 物理引擎进行动力学计算)：
		1. 全局配置 `<option>`：全局积分步长/亦对应真实控制频率（`timestep="0.01"`）；底层力学解算规则（`cone="elliptic"`）
		2. 以单个关节为单位/对象：定义其物理特性（质量、惯性张量、摩擦系数），几何特性（尺寸）与视觉特性
		3. 定义关节间关系，主要是运动学特性：物理实体间的运动学拓扑连接（限定平面运动的旋转与滑动约束）、相对空间坐标
		4. 感知系统：触觉传感器（`<sensor>`）
		5. 驱动系统：电机执行器（`<actuator>`，力矩控制/位移控制）
		6. 联动
	2. [暴露关节 ID API]（供上层强化学习环境（`env.py`）在每个交互步（`step`）中进行高频的状态读写，进而定义奖励函数以及终止判断等等）：
		1. Geom ID: 几何外观，如墙高
		2. SITE ID: 标记点世界坐标,计算目标距离；data.site_xpos[site_id]，调用 site（标记点）的世界坐标
		3. Body ID: 质量、惯性、质心世界坐标；data.xpos[body_id]调用 body 的质心世界坐标
	3. 其他：
		1. 辅助：固定相机视场（`camera`）。
-->
<mujoco model="planar manipulator - bring ball">

  <include file="./visual.xml"/>
  <include file="./skybox.xml"/>
  <include file="./materials.xml"/>
  <asset>
    <texture name="background" type="2d" file="./my-ground.png"/>
    <material name="background" texture="background" texrepeat="1 1" texuniform="true"/>
  </asset>

  <visual>
    <map shadowclip=".5"/>
    <quality shadowsize="2048"/>
  </visual>

  <!-- 一次 mj_step = 现实中的 0.01 秒，与电脑运行速度无关 -->
  <!-- 原值为 0.001 -->
  <!-- 通过 self.model.opt.timestep 修改 或 直接修改 -->
  <option timestep="0.01" cone="elliptic"/>

  <default>
    <geom friction=".7" solimp="0.9 0.97 0.001" solref=".005 1"/>
    <joint solimplimit="0 0.99 0.01" solreflimit=".005 1"/>
    <general ctrllimited="true"/>
    <tendon width="0.01"/>
    <site size=".003 .003 .003" material="site" group="3"/>

    <default class="arm">
      <geom type="capsule" material="self" density="500"/>
      <!-- hinge：所有转动关节都绕着 Y 轴（axis=0 -1 0）转动 -->
      <joint type="hinge" pos="0 0 0" axis="0 -1 0" limited="true"/>
      <default class="hand">
        <joint damping=".5" range="-10 60"/>
        <geom size=".008"/>
        <site  type="box" size=".018 .005 .005" pos=".022 0 -.002" euler="0 15 0" group="4"/>
        <default class="fingertip">
          <geom type="sphere" size=".008" material="effector"/>
          <joint damping=".01" stiffness=".01" range="-40 20"/>
          <site  size=".012 .005 .008" pos=".003 0 .003" group="4" euler="0 0 0"/>
        </default>
      </default>
    </default>

    <default class="object">
      <geom material="self"/>
    </default>

    <default class="task">
      <site rgba="0 0 0 0"/>
    </default>

    <default class="obstacle">
      <geom material="decoration" friction="0"/>
    </default>

    <default class="ghost">
      <geom material="target" contype="0" conaffinity="0"/>
    </default>
  </default>

  <worldbody>
    <!-- Arena -->
    <light name="light" directional="true" diffuse=".6 .6 .6" pos="0 0 1" dir="0 0.1 -1" specular=".3 .3 .3"/>
    <geom name="floor" type="plane" pos="0 0 0" size=".4 .2 10" material="background"/>
    <geom name="wall1" type="plane" pos="-.682843 0 .282843" size=".4 .2 10" material="background" zaxis="1 0 1" contype="0" conaffinity="0"/>
    <geom name="wall2" type="plane" pos=".682843 0 .282843" size=".4 .2 10" material="background" zaxis="-1 0 1" contype="0" conaffinity="0"/>
    <geom name="wall1_collider" type="box" pos="-.7394115 0 .2262745" size="5 .2 .08" quat="0.9238795 0 0.3826834 0" contype="1" conaffinity="1" rgba="0 0 0 0.001"/>
    <geom name="wall2_collider" type="box" pos=".7394115 0 .2262745" size="5 .2 .08" quat="0.9238795 0 -0.3826834 0" contype="1" conaffinity="1" rgba="0 0 0 0.001"/>
    <geom name="background" type="plane" pos="0 .2 .5" size="1 .5 10" material="background" zaxis="0 -1 0" contype="0" conaffinity="0"/>
    <camera name="fixed" pos="0.000 -1.300 0.514" xyaxes="1.000 0.000 0.000 0.000 0.000 1.000" fovy="60"/>
    <!-- "fixed"相机位置：
    xyaxes: 相机坐标系定义，用于微调相机的朝向
    fovy: 较大的 fovy 会提供更广的视野，但可能会引入更多的透视畸变；
    -->

    <!-- Wall(curriculum) -->
    <!-- 初始高度设为很低（比如 0.02），位置在机械臂(0)和球(0.4)中间 -->
    <geom name="curriculum_wall" 
          type="box" 
          pos="0.2 0 0.1" 
          size="0.01 0.1 0.1" 
          class="obstacle" 
          contype="1" 
          conaffinity="1" 
          rgba="0.8 0.2 0.2 1"/>

    <!-- Arm -->
    <geom name="arm_root" type="cylinder" fromto="0 -.022 .4 0 .022 .4" size=".024"
          material="decoration" contype="0" conaffinity="0"/>
    <body name="upper_arm" pos="0 0 .4" childclass="arm">
      <joint name="arm_root" damping="2" limited="false"/>
      <geom  name="upper_arm"  size=".02" fromto="0 0 0 0 0 .18"/>
      <body  name="middle_arm" pos="0 0 .18" childclass="arm">
        <joint name="arm_shoulder" damping="1.5" range="-160 160"/>
        <geom  name="middle_arm"  size=".017" fromto="0 0 0 0 0 .15"/>
        <body  name="lower_arm" pos="0 0 .15">
          <joint name="arm_elbow" damping="1" range="-160 160"/>
          <geom  name="lower_arm" size=".014" fromto="0 0 0 0 0 .12"/>
          <body  name="hand" pos="0 0 .12">
            <joint name="arm_wrist" damping=".5" range="-140 140" />
            <geom  name="hand" size=".011" fromto="0 0 0 0 0 .03"/>
            <geom  name="palm1"  fromto="0 0 .03  .03 0 .045" class="hand"/>
            <geom  name="palm2"  fromto="0 0 .03 -.03 0 .045" class="hand"/>
            <site  name="grasp" pos="0 0 .065"/>
            <body  name="pinch site" pos="0 0 .090">
              <site  name="pinch"/>
              <inertial pos="0 0 0" mass="1e-6" diaginertia="1e-12 1e-12 1e-12"/>
              <camera name="hand" pos="0 -.3 0" xyaxes="1 0 0 0 0 1" mode="track"/>
            </body>
            <site  name="palm_touch" type="box" group="4" size=".025 .005 .008" pos="0 0 .043"/>

            <body name="thumb" pos=".03 0 .045" euler="0 -90 0" childclass="hand">
              <joint name="thumb"/>
              <geom  name="thumb1"  fromto="0 0 0 .02 0 -.01" size=".007"/>
              <geom  name="thumb2"  fromto=".02 0 -.01 .04 0 -.01" size=".007"/>
              <site  name="thumb_touch" group="4"/>
              <body  name="thumbtip" pos=".05 0 -.01" childclass="fingertip">
                <joint name="thumbtip"/>
                <geom  name="thumbtip1" pos="-.003 0 0" />
                <geom  name="thumbtip2" pos=".003 0 0" />
                <site  name="thumbtip_touch" group="4"/>
              </body>
            </body>

            <body name="finger" pos="-.03 0 .045" euler="0 90 180" childclass="hand">
              <joint name="finger"/>
              <geom  name="finger1"  fromto="0 0 0 .02 0 -.01" size=".007" />
              <geom  name="finger2"  fromto=".02 0 -.01 .04 0 -.01" size=".007"/>
              <site  name="finger_touch"/>
              <body  name="fingertip" pos=".05 0 -.01" childclass="fingertip">
                <joint name="fingertip"/>
                <geom  name="fingertip1" pos="-.003 0 0" />
                <geom  name="fingertip2" pos=".003 0 0" />
                <site  name="fingertip_touch"/>
              </body>
            </body>
          </body>
        </body>
      </body>
    </body>

    <!-- prop: ball -->
    <!-- slide：沿 x,z 轴滑动；hinge：绕 y 轴旋转；没有沿 y 轴的 slide 关节，说明球在平面内移动 -->
    <body name="ball" pos=".4 0 .4" childclass="object">
      <joint name="ball_x" type="slide" axis="1 0 0" ref=".4"/>
      <joint name="ball_z" type="slide" axis="0 0 1" ref=".4"/>
      <joint name="ball_y" type="hinge" axis="0 1 0"/>
      <geom  name="ball" type="sphere" size=".022" />
      <site  name="ball" type="sphere"/>
    </body>

    <!-- target -->
    <!-- mocap="true"：虚拟点；不会受重力掉落，不参与物理碰撞（除非特殊设置），仅作为视觉和奖励参考 -->
    <body name="target_ball" pos=".4 .001 .4" mocap="true" childclass="ghost">
      <geom  name="target_ball" type="sphere" size=".02" />
      <site  name="target_ball" type="sphere"/>
    </body>

  </worldbody>

  <tendon>
    <fixed name="grasp">
      <joint joint="thumb"  coef=".5"/>
      <joint joint="finger" coef=".5"/>
    </fixed>
    <fixed name="coupling">
      <joint joint="thumb"  coef="-.5"/>
      <joint joint="finger" coef=".5"/>
    </fixed>
  </tendon>

  <equality>
    <tendon name="coupling" tendon1="coupling" solimp="0.95 0.99 0.001" solref=".005 .5"/>
  </equality>

  <sensor>
    <touch name="palm_touch" site="palm_touch"/>
    <touch name="finger_touch" site="finger_touch"/>
    <touch name="thumb_touch" site="thumb_touch"/>
    <touch name="fingertip_touch" site="fingertip_touch"/>
    <touch name="thumbtip_touch" site="thumbtip_touch"/>
  </sensor>

  <actuator>
    <motor name="root"     joint="arm_root"     ctrlrange="-1 1"  gear="12"/>
    <motor name="shoulder" joint="arm_shoulder" ctrlrange="-1 1"  gear="8"/>
    <motor name="elbow"    joint="arm_elbow"    ctrlrange="-1 1"  gear="4"/>
    <motor name="wrist"    joint="arm_wrist"    ctrlrange="-1 1"  gear="2"/>
    <motor name="grasp"    tendon="grasp"       ctrlrange="-1 1"  gear="2"/>
  </actuator>

</mujoco>